Traceback (most recent call last):
  File "/home/runner/micromamba-root/envs/clivar/lib/python3.10/site-packages/jupyter_cache/executors/utils.py", line 51, in single_nb_execution
    executenb(
  File "/home/runner/micromamba-root/envs/clivar/lib/python3.10/site-packages/nbclient/client.py", line 1204, in execute
    return NotebookClient(nb=nb, resources=resources, km=km, **kwargs).execute()
  File "/home/runner/micromamba-root/envs/clivar/lib/python3.10/site-packages/nbclient/util.py", line 84, in wrapped
    return just_run(coro(*args, **kwargs))
  File "/home/runner/micromamba-root/envs/clivar/lib/python3.10/site-packages/nbclient/util.py", line 62, in just_run
    return loop.run_until_complete(coro)
  File "/home/runner/micromamba-root/envs/clivar/lib/python3.10/asyncio/base_events.py", line 646, in run_until_complete
    return future.result()
  File "/home/runner/micromamba-root/envs/clivar/lib/python3.10/site-packages/nbclient/client.py", line 663, in async_execute
    await self.async_execute_cell(
  File "/home/runner/micromamba-root/envs/clivar/lib/python3.10/site-packages/nbclient/client.py", line 965, in async_execute_cell
    await self._check_raise_for_error(cell, cell_index, exec_reply)
  File "/home/runner/micromamba-root/envs/clivar/lib/python3.10/site-packages/nbclient/client.py", line 862, in _check_raise_for_error
    raise CellExecutionError.from_cell_and_msg(cell, exec_reply_content)
nbclient.exceptions.CellExecutionError: An error occurred while executing the following cell:
------------------
fs.ls('ESGF')
------------------

[0;31m---------------------------------------------------------------------------[0m
[0;31mClientError[0m                               Traceback (most recent call last)
File [0;32m~/micromamba-root/envs/clivar/lib/python3.10/site-packages/s3fs/core.py:646[0m, in [0;36mS3FileSystem._lsdir[0;34m(self, path, refresh, max_items, delimiter, prefix)[0m
[1;32m    645[0m dircache [38;5;241m=[39m []
[0;32m--> 646[0m [38;5;28;01masync[39;00m [38;5;28;01mfor[39;00m i [38;5;129;01min[39;00m it:
[1;32m    647[0m     dircache[38;5;241m.[39mextend(i[38;5;241m.[39mget([38;5;124m"[39m[38;5;124mCommonPrefixes[39m[38;5;124m"[39m, []))

File [0;32m~/micromamba-root/envs/clivar/lib/python3.10/site-packages/aiobotocore/paginate.py:30[0m, in [0;36mAioPageIterator.__anext__[0;34m(self)[0m
[1;32m     29[0m [38;5;28;01mwhile[39;00m [38;5;28;01mTrue[39;00m:
[0;32m---> 30[0m     response [38;5;241m=[39m [38;5;28;01mawait[39;00m [38;5;28mself[39m[38;5;241m.[39m_make_request(current_kwargs)
[1;32m     31[0m     parsed [38;5;241m=[39m [38;5;28mself[39m[38;5;241m.[39m_extract_parsed_response(response)

File [0;32m~/micromamba-root/envs/clivar/lib/python3.10/site-packages/aiobotocore/client.py:358[0m, in [0;36mAioBaseClient._make_api_call[0;34m(self, operation_name, api_params)[0m
[1;32m    357[0m     error_class [38;5;241m=[39m [38;5;28mself[39m[38;5;241m.[39mexceptions[38;5;241m.[39mfrom_code(error_code)
[0;32m--> 358[0m     [38;5;28;01mraise[39;00m error_class(parsed_response, operation_name)
[1;32m    359[0m [38;5;28;01melse[39;00m:

[0;31mClientError[0m: An error occurred (503) when calling the ListObjectsV2 operation (reached max retries: 4): Service Unavailable

The above exception was the direct cause of the following exception:

[0;31mOSError[0m                                   Traceback (most recent call last)
Cell [0;32mIn [3], line 1[0m
[0;32m----> 1[0m fs[38;5;241m.[39mls([38;5;124m'[39m[38;5;124mESGF[39m[38;5;124m'[39m)

File [0;32m~/micromamba-root/envs/clivar/lib/python3.10/site-packages/fsspec/asyn.py:111[0m, in [0;36msync_wrapper.<locals>.wrapper[0;34m(*args, **kwargs)[0m
[1;32m    108[0m [38;5;129m@functools[39m[38;5;241m.[39mwraps(func)
[1;32m    109[0m [38;5;28;01mdef[39;00m [38;5;21mwrapper[39m([38;5;241m*[39margs, [38;5;241m*[39m[38;5;241m*[39mkwargs):
[1;32m    110[0m     [38;5;28mself[39m [38;5;241m=[39m obj [38;5;129;01mor[39;00m args[[38;5;241m0[39m]
[0;32m--> 111[0m     [38;5;28;01mreturn[39;00m [43msync[49m[43m([49m[38;5;28;43mself[39;49m[38;5;241;43m.[39;49m[43mloop[49m[43m,[49m[43m [49m[43mfunc[49m[43m,[49m[43m [49m[38;5;241;43m*[39;49m[43margs[49m[43m,[49m[43m [49m[38;5;241;43m*[39;49m[38;5;241;43m*[39;49m[43mkwargs[49m[43m)[49m

File [0;32m~/micromamba-root/envs/clivar/lib/python3.10/site-packages/fsspec/asyn.py:96[0m, in [0;36msync[0;34m(loop, func, timeout, *args, **kwargs)[0m
[1;32m     94[0m     [38;5;28;01mraise[39;00m FSTimeoutError [38;5;28;01mfrom[39;00m [38;5;21;01mreturn_result[39;00m
[1;32m     95[0m [38;5;28;01melif[39;00m [38;5;28misinstance[39m(return_result, [38;5;167;01mBaseException[39;00m):
[0;32m---> 96[0m     [38;5;28;01mraise[39;00m return_result
[1;32m     97[0m [38;5;28;01melse[39;00m:
[1;32m     98[0m     [38;5;28;01mreturn[39;00m return_result

File [0;32m~/micromamba-root/envs/clivar/lib/python3.10/site-packages/fsspec/asyn.py:53[0m, in [0;36m_runner[0;34m(event, coro, result, timeout)[0m
[1;32m     51[0m     coro [38;5;241m=[39m asyncio[38;5;241m.[39mwait_for(coro, timeout[38;5;241m=[39mtimeout)
[1;32m     52[0m [38;5;28;01mtry[39;00m:
[0;32m---> 53[0m     result[[38;5;241m0[39m] [38;5;241m=[39m [38;5;28;01mawait[39;00m coro
[1;32m     54[0m [38;5;28;01mexcept[39;00m [38;5;167;01mException[39;00m [38;5;28;01mas[39;00m ex:
[1;32m     55[0m     result[[38;5;241m0[39m] [38;5;241m=[39m ex

File [0;32m~/micromamba-root/envs/clivar/lib/python3.10/site-packages/s3fs/core.py:863[0m, in [0;36mS3FileSystem._ls[0;34m(self, path, detail, refresh)[0m
[1;32m    861[0m     files [38;5;241m=[39m [38;5;28;01mawait[39;00m [38;5;28mself[39m[38;5;241m.[39m_lsbuckets(refresh)
[1;32m    862[0m [38;5;28;01melse[39;00m:
[0;32m--> 863[0m     files [38;5;241m=[39m [38;5;28;01mawait[39;00m [38;5;28mself[39m[38;5;241m.[39m_lsdir(path, refresh)
[1;32m    864[0m     [38;5;28;01mif[39;00m [38;5;129;01mnot[39;00m files [38;5;129;01mand[39;00m [38;5;124m"[39m[38;5;124m/[39m[38;5;124m"[39m [38;5;129;01min[39;00m path:
[1;32m    865[0m         files [38;5;241m=[39m [38;5;28;01mawait[39;00m [38;5;28mself[39m[38;5;241m.[39m_lsdir([38;5;28mself[39m[38;5;241m.[39m_parent(path), refresh[38;5;241m=[39mrefresh)

File [0;32m~/micromamba-root/envs/clivar/lib/python3.10/site-packages/s3fs/core.py:669[0m, in [0;36mS3FileSystem._lsdir[0;34m(self, path, refresh, max_items, delimiter, prefix)[0m
[1;32m    667[0m         f[[38;5;124m"[39m[38;5;124mname[39m[38;5;124m"[39m] [38;5;241m=[39m f[[38;5;124m"[39m[38;5;124mKey[39m[38;5;124m"[39m]
[1;32m    668[0m [38;5;28;01mexcept[39;00m ClientError [38;5;28;01mas[39;00m e:
[0;32m--> 669[0m     [38;5;28;01mraise[39;00m translate_boto_error(e)
[1;32m    671[0m [38;5;28;01mif[39;00m delimiter [38;5;129;01mand[39;00m files:
[1;32m    672[0m     [38;5;28mself[39m[38;5;241m.[39mdircache[path] [38;5;241m=[39m files

[0;31mOSError[0m: [Errno 16] Service Unavailable
OSError: [Errno 16] Service Unavailable

