Traceback (most recent call last):
  File "/home/runner/micromamba-root/envs/clivar/lib/python3.10/site-packages/jupyter_cache/executors/utils.py", line 51, in single_nb_execution
    executenb(
  File "/home/runner/micromamba-root/envs/clivar/lib/python3.10/site-packages/nbclient/client.py", line 1204, in execute
    return NotebookClient(nb=nb, resources=resources, km=km, **kwargs).execute()
  File "/home/runner/micromamba-root/envs/clivar/lib/python3.10/site-packages/nbclient/util.py", line 84, in wrapped
    return just_run(coro(*args, **kwargs))
  File "/home/runner/micromamba-root/envs/clivar/lib/python3.10/site-packages/nbclient/util.py", line 62, in just_run
    return loop.run_until_complete(coro)
  File "/home/runner/micromamba-root/envs/clivar/lib/python3.10/asyncio/base_events.py", line 646, in run_until_complete
    return future.result()
  File "/home/runner/micromamba-root/envs/clivar/lib/python3.10/site-packages/nbclient/client.py", line 663, in async_execute
    await self.async_execute_cell(
  File "/home/runner/micromamba-root/envs/clivar/lib/python3.10/site-packages/nbclient/client.py", line 965, in async_execute_cell
    await self._check_raise_for_error(cell, cell_index, exec_reply)
  File "/home/runner/micromamba-root/envs/clivar/lib/python3.10/site-packages/nbclient/client.py", line 862, in _check_raise_for_error
    raise CellExecutionError.from_cell_and_msg(cell, exec_reply_content)
nbclient.exceptions.CellExecutionError: An error occurred while executing the following cell:
------------------
# Iterate through remote_files to create a fileset
fileset = [fs.open(file) for file in remote_files]

# This works
dset = xr.open_mfdataset(fileset, combine='by_coords', use_cftime=True)
------------------

[0;31m---------------------------------------------------------------------------[0m
[0;31mOSError[0m                                   Traceback (most recent call last)
Cell [0;32mIn [6], line 5[0m
[1;32m      2[0m fileset [38;5;241m=[39m [fs[38;5;241m.[39mopen(file) [38;5;28;01mfor[39;00m file [38;5;129;01min[39;00m remote_files]
[1;32m      4[0m [38;5;66;03m# This works[39;00m
[0;32m----> 5[0m dset [38;5;241m=[39m xr[38;5;241m.[39mopen_mfdataset(fileset, combine[38;5;241m=[39m[38;5;124m'[39m[38;5;124mby_coords[39m[38;5;124m'[39m, use_cftime[38;5;241m=[39m[38;5;28;01mTrue[39;00m)

File [0;32m~/micromamba-root/envs/clivar/lib/python3.10/site-packages/xarray/backends/api.py:953[0m, in [0;36mopen_mfdataset[0;34m(paths, chunks, concat_dim, compat, preprocess, engine, data_vars, coords, combine, parallel, join, attrs_file, combine_attrs, **kwargs)[0m
[1;32m    950[0m     paths [38;5;241m=[39m [os[38;5;241m.[39mfspath(p) [38;5;28;01mif[39;00m [38;5;28misinstance[39m(p, os[38;5;241m.[39mPathLike) [38;5;28;01melse[39;00m p [38;5;28;01mfor[39;00m p [38;5;129;01min[39;00m paths]
[1;32m    952[0m [38;5;28;01mif[39;00m [38;5;129;01mnot[39;00m paths:
[0;32m--> 953[0m     [38;5;28;01mraise[39;00m [38;5;167;01mOSError[39;00m([38;5;124m"[39m[38;5;124mno files to open[39m[38;5;124m"[39m)
[1;32m    955[0m [38;5;28;01mif[39;00m combine [38;5;241m==[39m [38;5;124m"[39m[38;5;124mnested[39m[38;5;124m"[39m:
[1;32m    956[0m     [38;5;28;01mif[39;00m [38;5;28misinstance[39m(concat_dim, ([38;5;28mstr[39m, DataArray)) [38;5;129;01mor[39;00m concat_dim [38;5;129;01mis[39;00m [38;5;28;01mNone[39;00m:

[0;31mOSError[0m: no files to open
OSError: no files to open

